[2017-07-19 13:48:16 -0700] [655] [CRITICAL] WORKER TIMEOUT (pid:659)
[2017-07-19 13:48:16 -0700] [655] [CRITICAL] WORKER TIMEOUT (pid:660)
[2017-07-19 13:48:16 -0700] [655] [CRITICAL] WORKER TIMEOUT (pid:661)
[2017-07-19 13:48:16 -0700] [655] [CRITICAL] WORKER TIMEOUT (pid:662)
[2017-07-19 13:48:16 -0700] [655] [CRITICAL] WORKER TIMEOUT (pid:663)
[2017-07-19 13:48:16 -0700] [655] [CRITICAL] WORKER TIMEOUT (pid:664)
[2017-07-19 13:48:16 -0700] [655] [CRITICAL] WORKER TIMEOUT (pid:665)
[2017-07-19 13:48:16 -0700] [655] [CRITICAL] WORKER TIMEOUT (pid:666)
[2017-07-19 13:48:16 -0700] [655] [CRITICAL] WORKER TIMEOUT (pid:667)
2017-07-20 13:06:04,918 Exception on /ad [GET]
Traceback (most recent call last):
  File "/usr/local/lib/python2.7/site-packages/flask/app.py", line 1817, in wsgi_app
    response = self.full_dispatch_request()
  File "/usr/local/lib/python2.7/site-packages/flask/app.py", line 1477, in full_dispatch_request
    rv = self.handle_user_exception(e)
  File "/usr/local/lib/python2.7/site-packages/flask/app.py", line 1381, in handle_user_exception
    reraise(exc_type, exc_value, tb)
  File "/usr/local/lib/python2.7/site-packages/flask/app.py", line 1475, in full_dispatch_request
    rv = self.dispatch_request()
  File "/usr/local/lib/python2.7/site-packages/flask/app.py", line 1461, in dispatch_request
    return self.view_functions[rule.endpoint](**req.view_args)
  File "/usr/local/lib/python2.7/site-packages/psiturk/user_utils.py", line 20, in new_func
    resp = make_response(func(*args, **kwargs))
  File "/usr/local/lib/python2.7/site-packages/psiturk/experiment.py", line 270, in advertisement
    filter(Participant.workerid == worker_id).\
  File "/usr/local/lib/python2.7/site-packages/sqlalchemy/orm/query.py", line 2535, in count
    return self.from_self(col).scalar()
  File "/usr/local/lib/python2.7/site-packages/sqlalchemy/orm/query.py", line 2341, in scalar
    ret = self.one()
  File "/usr/local/lib/python2.7/site-packages/sqlalchemy/orm/query.py", line 2310, in one
    ret = list(self)
  File "/usr/local/lib/python2.7/site-packages/sqlalchemy/orm/query.py", line 2353, in __iter__
    return self._execute_and_instances(context)
  File "/usr/local/lib/python2.7/site-packages/sqlalchemy/orm/query.py", line 2368, in _execute_and_instances
    result = conn.execute(querycontext.statement, self._params)
  File "/usr/local/lib/python2.7/site-packages/sqlalchemy/engine/base.py", line 662, in execute
    params)
  File "/usr/local/lib/python2.7/site-packages/sqlalchemy/engine/base.py", line 761, in _execute_clauseelement
    compiled_sql, distilled_params
  File "/usr/local/lib/python2.7/site-packages/sqlalchemy/engine/base.py", line 874, in _execute_context
    context)
  File "/usr/local/lib/python2.7/site-packages/sqlalchemy/engine/base.py", line 1024, in _handle_dbapi_exception
    exc_info
  File "/usr/local/lib/python2.7/site-packages/sqlalchemy/util/compat.py", line 196, in raise_from_cause
    reraise(type(exception), exception, tb=exc_tb)
  File "/usr/local/lib/python2.7/site-packages/sqlalchemy/engine/base.py", line 867, in _execute_context
    context)
  File "/usr/local/lib/python2.7/site-packages/sqlalchemy/engine/default.py", line 324, in do_execute
    cursor.execute(statement, parameters)
OperationalError: (OperationalError) no such table: turkdemo u'SELECT count(*) AS count_1 \nFROM (SELECT turkdemo.uniqueid AS turkdemo_uniqueid, turkdemo.assignmentid AS turkdemo_assignmentid, turkdemo.workerid AS turkdemo_workerid, turkdemo.hitid AS turkdemo_hitid, turkdemo.ipaddress AS turkdemo_ipaddress, turkdemo.browser AS turkdemo_browser, turkdemo.platform AS turkdemo_platform, turkdemo.language AS turkdemo_language, turkdemo.cond AS turkdemo_cond, turkdemo.counterbalance AS turkdemo_counterbalance, turkdemo.codeversion AS turkdemo_codeversion, turkdemo.beginhit AS turkdemo_beginhit, turkdemo.beginexp AS turkdemo_beginexp, turkdemo.endhit AS turkdemo_endhit, turkdemo.bonus AS turkdemo_bonus, turkdemo.status AS turkdemo_status, turkdemo.datastring AS turkdemo_datastring \nFROM turkdemo \nWHERE turkdemo.assignmentid != ? AND turkdemo.workerid = ?) AS anon_1' (u'debugEWPVEL', u'debug4DSD3A')
2017-07-20 13:06:12,704 Exception on /ad [GET]
Traceback (most recent call last):
  File "/usr/local/lib/python2.7/site-packages/flask/app.py", line 1817, in wsgi_app
    response = self.full_dispatch_request()
  File "/usr/local/lib/python2.7/site-packages/flask/app.py", line 1477, in full_dispatch_request
    rv = self.handle_user_exception(e)
  File "/usr/local/lib/python2.7/site-packages/flask/app.py", line 1381, in handle_user_exception
    reraise(exc_type, exc_value, tb)
  File "/usr/local/lib/python2.7/site-packages/flask/app.py", line 1475, in full_dispatch_request
    rv = self.dispatch_request()
  File "/usr/local/lib/python2.7/site-packages/flask/app.py", line 1461, in dispatch_request
    return self.view_functions[rule.endpoint](**req.view_args)
  File "/usr/local/lib/python2.7/site-packages/psiturk/user_utils.py", line 20, in new_func
    resp = make_response(func(*args, **kwargs))
  File "/usr/local/lib/python2.7/site-packages/psiturk/experiment.py", line 270, in advertisement
    filter(Participant.workerid == worker_id).\
  File "/usr/local/lib/python2.7/site-packages/sqlalchemy/orm/query.py", line 2535, in count
    return self.from_self(col).scalar()
  File "/usr/local/lib/python2.7/site-packages/sqlalchemy/orm/query.py", line 2341, in scalar
    ret = self.one()
  File "/usr/local/lib/python2.7/site-packages/sqlalchemy/orm/query.py", line 2310, in one
    ret = list(self)
  File "/usr/local/lib/python2.7/site-packages/sqlalchemy/orm/query.py", line 2353, in __iter__
    return self._execute_and_instances(context)
  File "/usr/local/lib/python2.7/site-packages/sqlalchemy/orm/query.py", line 2368, in _execute_and_instances
    result = conn.execute(querycontext.statement, self._params)
  File "/usr/local/lib/python2.7/site-packages/sqlalchemy/engine/base.py", line 662, in execute
    params)
  File "/usr/local/lib/python2.7/site-packages/sqlalchemy/engine/base.py", line 761, in _execute_clauseelement
    compiled_sql, distilled_params
  File "/usr/local/lib/python2.7/site-packages/sqlalchemy/engine/base.py", line 874, in _execute_context
    context)
  File "/usr/local/lib/python2.7/site-packages/sqlalchemy/engine/base.py", line 1024, in _handle_dbapi_exception
    exc_info
  File "/usr/local/lib/python2.7/site-packages/sqlalchemy/util/compat.py", line 196, in raise_from_cause
    reraise(type(exception), exception, tb=exc_tb)
  File "/usr/local/lib/python2.7/site-packages/sqlalchemy/engine/base.py", line 867, in _execute_context
    context)
  File "/usr/local/lib/python2.7/site-packages/sqlalchemy/engine/default.py", line 324, in do_execute
    cursor.execute(statement, parameters)
OperationalError: (OperationalError) no such table: turkdemo u'SELECT count(*) AS count_1 \nFROM (SELECT turkdemo.uniqueid AS turkdemo_uniqueid, turkdemo.assignmentid AS turkdemo_assignmentid, turkdemo.workerid AS turkdemo_workerid, turkdemo.hitid AS turkdemo_hitid, turkdemo.ipaddress AS turkdemo_ipaddress, turkdemo.browser AS turkdemo_browser, turkdemo.platform AS turkdemo_platform, turkdemo.language AS turkdemo_language, turkdemo.cond AS turkdemo_cond, turkdemo.counterbalance AS turkdemo_counterbalance, turkdemo.codeversion AS turkdemo_codeversion, turkdemo.beginhit AS turkdemo_beginhit, turkdemo.beginexp AS turkdemo_beginexp, turkdemo.endhit AS turkdemo_endhit, turkdemo.bonus AS turkdemo_bonus, turkdemo.status AS turkdemo_status, turkdemo.datastring AS turkdemo_datastring \nFROM turkdemo \nWHERE turkdemo.assignmentid != ? AND turkdemo.workerid = ?) AS anon_1' (u'debug21WA8H', u'debugKD89EO')
2017-07-20 13:06:23,495 Exception on /ad [GET]
Traceback (most recent call last):
  File "/usr/local/lib/python2.7/site-packages/flask/app.py", line 1817, in wsgi_app
    response = self.full_dispatch_request()
  File "/usr/local/lib/python2.7/site-packages/flask/app.py", line 1477, in full_dispatch_request
    rv = self.handle_user_exception(e)
  File "/usr/local/lib/python2.7/site-packages/flask/app.py", line 1381, in handle_user_exception
    reraise(exc_type, exc_value, tb)
  File "/usr/local/lib/python2.7/site-packages/flask/app.py", line 1475, in full_dispatch_request
    rv = self.dispatch_request()
  File "/usr/local/lib/python2.7/site-packages/flask/app.py", line 1461, in dispatch_request
    return self.view_functions[rule.endpoint](**req.view_args)
  File "/usr/local/lib/python2.7/site-packages/psiturk/user_utils.py", line 20, in new_func
    resp = make_response(func(*args, **kwargs))
  File "/usr/local/lib/python2.7/site-packages/psiturk/experiment.py", line 270, in advertisement
    filter(Participant.workerid == worker_id).\
  File "/usr/local/lib/python2.7/site-packages/sqlalchemy/orm/query.py", line 2535, in count
    return self.from_self(col).scalar()
  File "/usr/local/lib/python2.7/site-packages/sqlalchemy/orm/query.py", line 2341, in scalar
    ret = self.one()
  File "/usr/local/lib/python2.7/site-packages/sqlalchemy/orm/query.py", line 2310, in one
    ret = list(self)
  File "/usr/local/lib/python2.7/site-packages/sqlalchemy/orm/query.py", line 2353, in __iter__
    return self._execute_and_instances(context)
  File "/usr/local/lib/python2.7/site-packages/sqlalchemy/orm/query.py", line 2368, in _execute_and_instances
    result = conn.execute(querycontext.statement, self._params)
  File "/usr/local/lib/python2.7/site-packages/sqlalchemy/engine/base.py", line 662, in execute
    params)
  File "/usr/local/lib/python2.7/site-packages/sqlalchemy/engine/base.py", line 761, in _execute_clauseelement
    compiled_sql, distilled_params
  File "/usr/local/lib/python2.7/site-packages/sqlalchemy/engine/base.py", line 874, in _execute_context
    context)
  File "/usr/local/lib/python2.7/site-packages/sqlalchemy/engine/base.py", line 1024, in _handle_dbapi_exception
    exc_info
  File "/usr/local/lib/python2.7/site-packages/sqlalchemy/util/compat.py", line 196, in raise_from_cause
    reraise(type(exception), exception, tb=exc_tb)
  File "/usr/local/lib/python2.7/site-packages/sqlalchemy/engine/base.py", line 867, in _execute_context
    context)
  File "/usr/local/lib/python2.7/site-packages/sqlalchemy/engine/default.py", line 324, in do_execute
    cursor.execute(statement, parameters)
OperationalError: (OperationalError) no such table: turkdemo u'SELECT count(*) AS count_1 \nFROM (SELECT turkdemo.uniqueid AS turkdemo_uniqueid, turkdemo.assignmentid AS turkdemo_assignmentid, turkdemo.workerid AS turkdemo_workerid, turkdemo.hitid AS turkdemo_hitid, turkdemo.ipaddress AS turkdemo_ipaddress, turkdemo.browser AS turkdemo_browser, turkdemo.platform AS turkdemo_platform, turkdemo.language AS turkdemo_language, turkdemo.cond AS turkdemo_cond, turkdemo.counterbalance AS turkdemo_counterbalance, turkdemo.codeversion AS turkdemo_codeversion, turkdemo.beginhit AS turkdemo_beginhit, turkdemo.beginexp AS turkdemo_beginexp, turkdemo.endhit AS turkdemo_endhit, turkdemo.bonus AS turkdemo_bonus, turkdemo.status AS turkdemo_status, turkdemo.datastring AS turkdemo_datastring \nFROM turkdemo \nWHERE turkdemo.assignmentid != ? AND turkdemo.workerid = ?) AS anon_1' (u'debugTFK34P', u'debugOIO3VM')
2017-07-20 13:06:33,218 Exception on /ad [GET]
Traceback (most recent call last):
  File "/usr/local/lib/python2.7/site-packages/flask/app.py", line 1817, in wsgi_app
    response = self.full_dispatch_request()
  File "/usr/local/lib/python2.7/site-packages/flask/app.py", line 1477, in full_dispatch_request
    rv = self.handle_user_exception(e)
  File "/usr/local/lib/python2.7/site-packages/flask/app.py", line 1381, in handle_user_exception
    reraise(exc_type, exc_value, tb)
  File "/usr/local/lib/python2.7/site-packages/flask/app.py", line 1475, in full_dispatch_request
    rv = self.dispatch_request()
  File "/usr/local/lib/python2.7/site-packages/flask/app.py", line 1461, in dispatch_request
    return self.view_functions[rule.endpoint](**req.view_args)
  File "/usr/local/lib/python2.7/site-packages/psiturk/user_utils.py", line 20, in new_func
    resp = make_response(func(*args, **kwargs))
  File "/usr/local/lib/python2.7/site-packages/psiturk/experiment.py", line 270, in advertisement
    filter(Participant.workerid == worker_id).\
  File "/usr/local/lib/python2.7/site-packages/sqlalchemy/orm/query.py", line 2535, in count
    return self.from_self(col).scalar()
  File "/usr/local/lib/python2.7/site-packages/sqlalchemy/orm/query.py", line 2341, in scalar
    ret = self.one()
  File "/usr/local/lib/python2.7/site-packages/sqlalchemy/orm/query.py", line 2310, in one
    ret = list(self)
  File "/usr/local/lib/python2.7/site-packages/sqlalchemy/orm/query.py", line 2353, in __iter__
    return self._execute_and_instances(context)
  File "/usr/local/lib/python2.7/site-packages/sqlalchemy/orm/query.py", line 2368, in _execute_and_instances
    result = conn.execute(querycontext.statement, self._params)
  File "/usr/local/lib/python2.7/site-packages/sqlalchemy/engine/base.py", line 662, in execute
    params)
  File "/usr/local/lib/python2.7/site-packages/sqlalchemy/engine/base.py", line 761, in _execute_clauseelement
    compiled_sql, distilled_params
  File "/usr/local/lib/python2.7/site-packages/sqlalchemy/engine/base.py", line 874, in _execute_context
    context)
  File "/usr/local/lib/python2.7/site-packages/sqlalchemy/engine/base.py", line 1024, in _handle_dbapi_exception
    exc_info
  File "/usr/local/lib/python2.7/site-packages/sqlalchemy/util/compat.py", line 196, in raise_from_cause
    reraise(type(exception), exception, tb=exc_tb)
  File "/usr/local/lib/python2.7/site-packages/sqlalchemy/engine/base.py", line 867, in _execute_context
    context)
  File "/usr/local/lib/python2.7/site-packages/sqlalchemy/engine/default.py", line 324, in do_execute
    cursor.execute(statement, parameters)
OperationalError: (OperationalError) no such table: turkdemo u'SELECT count(*) AS count_1 \nFROM (SELECT turkdemo.uniqueid AS turkdemo_uniqueid, turkdemo.assignmentid AS turkdemo_assignmentid, turkdemo.workerid AS turkdemo_workerid, turkdemo.hitid AS turkdemo_hitid, turkdemo.ipaddress AS turkdemo_ipaddress, turkdemo.browser AS turkdemo_browser, turkdemo.platform AS turkdemo_platform, turkdemo.language AS turkdemo_language, turkdemo.cond AS turkdemo_cond, turkdemo.counterbalance AS turkdemo_counterbalance, turkdemo.codeversion AS turkdemo_codeversion, turkdemo.beginhit AS turkdemo_beginhit, turkdemo.beginexp AS turkdemo_beginexp, turkdemo.endhit AS turkdemo_endhit, turkdemo.bonus AS turkdemo_bonus, turkdemo.status AS turkdemo_status, turkdemo.datastring AS turkdemo_datastring \nFROM turkdemo \nWHERE turkdemo.assignmentid != ? AND turkdemo.workerid = ?) AS anon_1' (u'debugNL4Y9T', u'debug66NU9W')
2017-07-20 13:06:47,074 Exception on /ad [GET]
Traceback (most recent call last):
  File "/usr/local/lib/python2.7/site-packages/flask/app.py", line 1817, in wsgi_app
    response = self.full_dispatch_request()
  File "/usr/local/lib/python2.7/site-packages/flask/app.py", line 1477, in full_dispatch_request
    rv = self.handle_user_exception(e)
  File "/usr/local/lib/python2.7/site-packages/flask/app.py", line 1381, in handle_user_exception
    reraise(exc_type, exc_value, tb)
  File "/usr/local/lib/python2.7/site-packages/flask/app.py", line 1475, in full_dispatch_request
    rv = self.dispatch_request()
  File "/usr/local/lib/python2.7/site-packages/flask/app.py", line 1461, in dispatch_request
    return self.view_functions[rule.endpoint](**req.view_args)
  File "/usr/local/lib/python2.7/site-packages/psiturk/user_utils.py", line 20, in new_func
    resp = make_response(func(*args, **kwargs))
  File "/usr/local/lib/python2.7/site-packages/psiturk/experiment.py", line 270, in advertisement
    filter(Participant.workerid == worker_id).\
  File "/usr/local/lib/python2.7/site-packages/sqlalchemy/orm/query.py", line 2535, in count
    return self.from_self(col).scalar()
  File "/usr/local/lib/python2.7/site-packages/sqlalchemy/orm/query.py", line 2341, in scalar
    ret = self.one()
  File "/usr/local/lib/python2.7/site-packages/sqlalchemy/orm/query.py", line 2310, in one
    ret = list(self)
  File "/usr/local/lib/python2.7/site-packages/sqlalchemy/orm/query.py", line 2353, in __iter__
    return self._execute_and_instances(context)
  File "/usr/local/lib/python2.7/site-packages/sqlalchemy/orm/query.py", line 2368, in _execute_and_instances
    result = conn.execute(querycontext.statement, self._params)
  File "/usr/local/lib/python2.7/site-packages/sqlalchemy/engine/base.py", line 662, in execute
    params)
  File "/usr/local/lib/python2.7/site-packages/sqlalchemy/engine/base.py", line 761, in _execute_clauseelement
    compiled_sql, distilled_params
  File "/usr/local/lib/python2.7/site-packages/sqlalchemy/engine/base.py", line 874, in _execute_context
    context)
  File "/usr/local/lib/python2.7/site-packages/sqlalchemy/engine/base.py", line 1024, in _handle_dbapi_exception
    exc_info
  File "/usr/local/lib/python2.7/site-packages/sqlalchemy/util/compat.py", line 196, in raise_from_cause
    reraise(type(exception), exception, tb=exc_tb)
  File "/usr/local/lib/python2.7/site-packages/sqlalchemy/engine/base.py", line 867, in _execute_context
    context)
  File "/usr/local/lib/python2.7/site-packages/sqlalchemy/engine/default.py", line 324, in do_execute
    cursor.execute(statement, parameters)
OperationalError: (OperationalError) no such table: turkdemo u'SELECT count(*) AS count_1 \nFROM (SELECT turkdemo.uniqueid AS turkdemo_uniqueid, turkdemo.assignmentid AS turkdemo_assignmentid, turkdemo.workerid AS turkdemo_workerid, turkdemo.hitid AS turkdemo_hitid, turkdemo.ipaddress AS turkdemo_ipaddress, turkdemo.browser AS turkdemo_browser, turkdemo.platform AS turkdemo_platform, turkdemo.language AS turkdemo_language, turkdemo.cond AS turkdemo_cond, turkdemo.counterbalance AS turkdemo_counterbalance, turkdemo.codeversion AS turkdemo_codeversion, turkdemo.beginhit AS turkdemo_beginhit, turkdemo.beginexp AS turkdemo_beginexp, turkdemo.endhit AS turkdemo_endhit, turkdemo.bonus AS turkdemo_bonus, turkdemo.status AS turkdemo_status, turkdemo.datastring AS turkdemo_datastring \nFROM turkdemo \nWHERE turkdemo.assignmentid != ? AND turkdemo.workerid = ?) AS anon_1' (u'debugXSYRRB', u'debugRNLRV0')
[2017-07-20 16:29:27 -0700] [3365] [CRITICAL] WORKER TIMEOUT (pid:3369)
[2017-07-20 16:29:27 -0700] [3365] [CRITICAL] WORKER TIMEOUT (pid:3371)
[2017-07-20 16:29:27 -0700] [3365] [CRITICAL] WORKER TIMEOUT (pid:3372)
[2017-07-20 16:29:27 -0700] [3365] [CRITICAL] WORKER TIMEOUT (pid:3373)
[2017-07-20 16:29:27 -0700] [3365] [CRITICAL] WORKER TIMEOUT (pid:3374)
[2017-07-20 16:29:27 -0700] [3365] [CRITICAL] WORKER TIMEOUT (pid:3375)
[2017-07-20 16:29:27 -0700] [3365] [CRITICAL] WORKER TIMEOUT (pid:3376)
[2017-07-20 16:29:27 -0700] [3365] [CRITICAL] WORKER TIMEOUT (pid:3377)
[2017-07-20 16:29:27 -0700] [3365] [CRITICAL] WORKER TIMEOUT (pid:3378)
[2017-07-21 13:43:29 -0700] [1835] [CRITICAL] WORKER TIMEOUT (pid:1839)
[2017-07-21 13:43:29 -0700] [1835] [CRITICAL] WORKER TIMEOUT (pid:1840)
[2017-07-21 13:43:29 -0700] [1835] [CRITICAL] WORKER TIMEOUT (pid:1842)
[2017-07-21 13:43:29 -0700] [1835] [CRITICAL] WORKER TIMEOUT (pid:1843)
[2017-07-21 13:43:29 -0700] [1835] [CRITICAL] WORKER TIMEOUT (pid:1844)
[2017-07-21 13:43:29 -0700] [1835] [CRITICAL] WORKER TIMEOUT (pid:1845)
[2017-07-21 13:43:29 -0700] [1835] [CRITICAL] WORKER TIMEOUT (pid:1846)
[2017-07-21 13:43:29 -0700] [1835] [CRITICAL] WORKER TIMEOUT (pid:1847)
[2017-07-21 13:43:29 -0700] [1835] [CRITICAL] WORKER TIMEOUT (pid:1848)
2017-07-21 13:52:28,570 Exception on /new_config.txt [GET]
Traceback (most recent call last):
  File "/usr/local/lib/python2.7/site-packages/flask/app.py", line 1817, in wsgi_app
    response = self.full_dispatch_request()
  File "/usr/local/lib/python2.7/site-packages/flask/app.py", line 1477, in full_dispatch_request
    rv = self.handle_user_exception(e)
  File "/usr/local/lib/python2.7/site-packages/flask/app.py", line 1381, in handle_user_exception
    reraise(exc_type, exc_value, tb)
  File "/usr/local/lib/python2.7/site-packages/flask/app.py", line 1475, in full_dispatch_request
    rv = self.dispatch_request()
  File "/usr/local/lib/python2.7/site-packages/flask/app.py", line 1461, in dispatch_request
    return self.view_functions[rule.endpoint](**req.view_args)
  File "/usr/local/lib/python2.7/site-packages/psiturk/experiment.py", line 713, in regularpage
    return render_template(pagename)
  File "/usr/local/lib/python2.7/site-packages/flask/templating.py", line 127, in render_template
    return _render(ctx.app.jinja_env.get_or_select_template(template_name_or_list),
  File "/usr/local/lib/python2.7/site-packages/jinja2/environment.py", line 869, in get_or_select_template
    return self.get_template(template_name_or_list, parent, globals)
  File "/usr/local/lib/python2.7/site-packages/jinja2/environment.py", line 830, in get_template
    return self._load_template(name, self.make_globals(globals))
  File "/usr/local/lib/python2.7/site-packages/jinja2/environment.py", line 804, in _load_template
    template = self.loader.load(self, name, globals)
  File "/usr/local/lib/python2.7/site-packages/jinja2/loaders.py", line 113, in load
    source, filename, uptodate = self.get_source(environment, name)
  File "/usr/local/lib/python2.7/site-packages/flask/templating.py", line 64, in get_source
    raise TemplateNotFound(template)
TemplateNotFound: new_config.txt
2017-07-21 14:16:35,036 Exception on /new_config.txt [GET]
Traceback (most recent call last):
  File "/usr/local/lib/python2.7/site-packages/flask/app.py", line 1817, in wsgi_app
    response = self.full_dispatch_request()
  File "/usr/local/lib/python2.7/site-packages/flask/app.py", line 1477, in full_dispatch_request
    rv = self.handle_user_exception(e)
  File "/usr/local/lib/python2.7/site-packages/flask/app.py", line 1381, in handle_user_exception
    reraise(exc_type, exc_value, tb)
  File "/usr/local/lib/python2.7/site-packages/flask/app.py", line 1475, in full_dispatch_request
    rv = self.dispatch_request()
  File "/usr/local/lib/python2.7/site-packages/flask/app.py", line 1461, in dispatch_request
    return self.view_functions[rule.endpoint](**req.view_args)
  File "/usr/local/lib/python2.7/site-packages/psiturk/experiment.py", line 713, in regularpage
    return render_template(pagename)
  File "/usr/local/lib/python2.7/site-packages/flask/templating.py", line 127, in render_template
    return _render(ctx.app.jinja_env.get_or_select_template(template_name_or_list),
  File "/usr/local/lib/python2.7/site-packages/jinja2/environment.py", line 869, in get_or_select_template
    return self.get_template(template_name_or_list, parent, globals)
  File "/usr/local/lib/python2.7/site-packages/jinja2/environment.py", line 830, in get_template
    return self._load_template(name, self.make_globals(globals))
  File "/usr/local/lib/python2.7/site-packages/jinja2/environment.py", line 804, in _load_template
    template = self.loader.load(self, name, globals)
  File "/usr/local/lib/python2.7/site-packages/jinja2/loaders.py", line 113, in load
    source, filename, uptodate = self.get_source(environment, name)
  File "/usr/local/lib/python2.7/site-packages/flask/templating.py", line 64, in get_source
    raise TemplateNotFound(template)
TemplateNotFound: new_config.txt
2017-07-21 14:52:32,887 Exception on /new_config.txt [GET]
Traceback (most recent call last):
  File "/usr/local/lib/python2.7/site-packages/flask/app.py", line 1817, in wsgi_app
    response = self.full_dispatch_request()
  File "/usr/local/lib/python2.7/site-packages/flask/app.py", line 1477, in full_dispatch_request
    rv = self.handle_user_exception(e)
  File "/usr/local/lib/python2.7/site-packages/flask/app.py", line 1381, in handle_user_exception
    reraise(exc_type, exc_value, tb)
  File "/usr/local/lib/python2.7/site-packages/flask/app.py", line 1475, in full_dispatch_request
    rv = self.dispatch_request()
  File "/usr/local/lib/python2.7/site-packages/flask/app.py", line 1461, in dispatch_request
    return self.view_functions[rule.endpoint](**req.view_args)
  File "/usr/local/lib/python2.7/site-packages/psiturk/experiment.py", line 713, in regularpage
    return render_template(pagename)
  File "/usr/local/lib/python2.7/site-packages/flask/templating.py", line 127, in render_template
    return _render(ctx.app.jinja_env.get_or_select_template(template_name_or_list),
  File "/usr/local/lib/python2.7/site-packages/jinja2/environment.py", line 869, in get_or_select_template
    return self.get_template(template_name_or_list, parent, globals)
  File "/usr/local/lib/python2.7/site-packages/jinja2/environment.py", line 830, in get_template
    return self._load_template(name, self.make_globals(globals))
  File "/usr/local/lib/python2.7/site-packages/jinja2/environment.py", line 804, in _load_template
    template = self.loader.load(self, name, globals)
  File "/usr/local/lib/python2.7/site-packages/jinja2/loaders.py", line 113, in load
    source, filename, uptodate = self.get_source(environment, name)
  File "/usr/local/lib/python2.7/site-packages/flask/templating.py", line 64, in get_source
    raise TemplateNotFound(template)
TemplateNotFound: new_config.txt
2017-07-21 14:59:27,635 Exception on /new_config.txt [GET]
Traceback (most recent call last):
  File "/usr/local/lib/python2.7/site-packages/flask/app.py", line 1817, in wsgi_app
    response = self.full_dispatch_request()
  File "/usr/local/lib/python2.7/site-packages/flask/app.py", line 1477, in full_dispatch_request
    rv = self.handle_user_exception(e)
  File "/usr/local/lib/python2.7/site-packages/flask/app.py", line 1381, in handle_user_exception
    reraise(exc_type, exc_value, tb)
  File "/usr/local/lib/python2.7/site-packages/flask/app.py", line 1475, in full_dispatch_request
    rv = self.dispatch_request()
  File "/usr/local/lib/python2.7/site-packages/flask/app.py", line 1461, in dispatch_request
    return self.view_functions[rule.endpoint](**req.view_args)
  File "/usr/local/lib/python2.7/site-packages/psiturk/experiment.py", line 713, in regularpage
    return render_template(pagename)
  File "/usr/local/lib/python2.7/site-packages/flask/templating.py", line 127, in render_template
    return _render(ctx.app.jinja_env.get_or_select_template(template_name_or_list),
  File "/usr/local/lib/python2.7/site-packages/jinja2/environment.py", line 869, in get_or_select_template
    return self.get_template(template_name_or_list, parent, globals)
  File "/usr/local/lib/python2.7/site-packages/jinja2/environment.py", line 830, in get_template
    return self._load_template(name, self.make_globals(globals))
  File "/usr/local/lib/python2.7/site-packages/jinja2/environment.py", line 804, in _load_template
    template = self.loader.load(self, name, globals)
  File "/usr/local/lib/python2.7/site-packages/jinja2/loaders.py", line 113, in load
    source, filename, uptodate = self.get_source(environment, name)
  File "/usr/local/lib/python2.7/site-packages/flask/templating.py", line 64, in get_source
    raise TemplateNotFound(template)
TemplateNotFound: new_config.txt
2017-07-21 15:01:19,870 Exception on /new_config.txt [GET]
Traceback (most recent call last):
  File "/usr/local/lib/python2.7/site-packages/flask/app.py", line 1817, in wsgi_app
    response = self.full_dispatch_request()
  File "/usr/local/lib/python2.7/site-packages/flask/app.py", line 1477, in full_dispatch_request
    rv = self.handle_user_exception(e)
  File "/usr/local/lib/python2.7/site-packages/flask/app.py", line 1381, in handle_user_exception
    reraise(exc_type, exc_value, tb)
  File "/usr/local/lib/python2.7/site-packages/flask/app.py", line 1475, in full_dispatch_request
    rv = self.dispatch_request()
  File "/usr/local/lib/python2.7/site-packages/flask/app.py", line 1461, in dispatch_request
    return self.view_functions[rule.endpoint](**req.view_args)
  File "/usr/local/lib/python2.7/site-packages/psiturk/experiment.py", line 713, in regularpage
    return render_template(pagename)
  File "/usr/local/lib/python2.7/site-packages/flask/templating.py", line 127, in render_template
    return _render(ctx.app.jinja_env.get_or_select_template(template_name_or_list),
  File "/usr/local/lib/python2.7/site-packages/jinja2/environment.py", line 869, in get_or_select_template
    return self.get_template(template_name_or_list, parent, globals)
  File "/usr/local/lib/python2.7/site-packages/jinja2/environment.py", line 830, in get_template
    return self._load_template(name, self.make_globals(globals))
  File "/usr/local/lib/python2.7/site-packages/jinja2/environment.py", line 804, in _load_template
    template = self.loader.load(self, name, globals)
  File "/usr/local/lib/python2.7/site-packages/jinja2/loaders.py", line 113, in load
    source, filename, uptodate = self.get_source(environment, name)
  File "/usr/local/lib/python2.7/site-packages/flask/templating.py", line 64, in get_source
    raise TemplateNotFound(template)
TemplateNotFound: new_config.txt
